<?xml version="1.0" encoding="UTF-8"?>
<!-- Generated by org.testng.reporters.JUnitReportReporter -->
<testsuite hostname="BAH5Q3C9J3" failures="2" tests="21" name="RetryAllTestCases.MyTests" time="0.015" errors="0" timestamp="2023-03-21T16:49:37 EDT" skipped="19">
  <testcase classname="RetryAllTestCases.MyTests" name="test2" time="0.000">
    <skipped/>
  </testcase> <!-- test2 -->
  <system-out/>
  <testcase classname="RetryAllTestCases.MyTests" name="test1" time="0.000">
    <skipped/>
  </testcase> <!-- test1 -->
  <system-out/>
  <testcase classname="RetryAllTestCases.MyTests" name="test1" time="0.000">
    <skipped/>
  </testcase> <!-- test1 -->
  <system-out/>
  <testcase classname="RetryAllTestCases.MyTests" name="test2" time="0.000">
    <skipped/>
  </testcase> <!-- test2 -->
  <system-out/>
  <testcase classname="RetryAllTestCases.MyTests" name="test1" time="0.008">
    <skipped/>
  </testcase> <!-- test1 -->
  <system-out/>
  <testcase classname="RetryAllTestCases.MyTests" name="test1" time="0.001">
    <skipped/>
  </testcase> <!-- test1 -->
  <system-out/>
  <testcase classname="RetryAllTestCases.MyTests" name="test2" time="0.000">
    <skipped/>
  </testcase> <!-- test2 -->
  <system-out/>
  <testcase classname="RetryAllTestCases.MyTests" name="test1" time="0.000">
    <failure message="expected [false] but found [true]" type="java.lang.AssertionError">
      <![CDATA[java.lang.AssertionError: expected [false] but found [true]
at org.testng.Assert.fail(Assert.java:99)
at org.testng.Assert.failNotEquals(Assert.java:1037)
at org.testng.Assert.assertEqualsImpl(Assert.java:140)
at org.testng.Assert.assertEquals(Assert.java:122)
at org.testng.Assert.assertEquals(Assert.java:819)
at org.testng.Assert.assertEquals(Assert.java:829)
at RetryAllTestCases.MyTests.test1(MyTests.java:11)
at java.base/jdk.internal.reflect.DirectMethodHandleAccessor.invoke(DirectMethodHandleAccessor.java:104)
at java.base/java.lang.reflect.Method.invoke(Method.java:578)
at org.testng.internal.MethodInvocationHelper.invokeMethod(MethodInvocationHelper.java:133)
at org.testng.internal.TestInvoker.invokeMethod(TestInvoker.java:598)
at org.testng.internal.TestInvoker.retryFailed(TestInvoker.java:213)
at org.testng.internal.MethodRunner.runInSequence(MethodRunner.java:58)
at org.testng.internal.TestInvoker$MethodInvocationAgent.invoke(TestInvoker.java:824)
at org.testng.internal.TestInvoker.invokeTestMethods(TestInvoker.java:146)
at org.testng.internal.TestMethodWorker.invokeTestMethods(TestMethodWorker.java:146)
at org.testng.internal.TestMethodWorker.run(TestMethodWorker.java:128)
at java.base/java.util.ArrayList.forEach(ArrayList.java:1511)
at org.testng.TestRunner.privateRun(TestRunner.java:794)
at org.testng.TestRunner.run(TestRunner.java:596)
at org.testng.SuiteRunner.runTest(SuiteRunner.java:377)
at org.testng.SuiteRunner.runSequentially(SuiteRunner.java:371)
at org.testng.SuiteRunner.privateRun(SuiteRunner.java:332)
at org.testng.SuiteRunner.run(SuiteRunner.java:276)
at org.testng.SuiteRunnerWorker.runSuite(SuiteRunnerWorker.java:53)
at org.testng.SuiteRunnerWorker.run(SuiteRunnerWorker.java:96)
at org.testng.TestNG.runSuitesSequentially(TestNG.java:1212)
at org.testng.TestNG.runSuitesLocally(TestNG.java:1134)
at org.testng.TestNG.runSuites(TestNG.java:1063)
at org.testng.TestNG.run(TestNG.java:1031)
at org.testng.remote.AbstractRemoteTestNG.run(AbstractRemoteTestNG.java:115)
at org.testng.remote.RemoteTestNG.initAndRun(RemoteTestNG.java:251)
at org.testng.remote.RemoteTestNG.main(RemoteTestNG.java:77)
]]>
    </failure>
  </testcase> <!-- test1 -->
  <system-out/>
  <testcase classname="RetryAllTestCases.MyTests" name="test1" time="0.001">
    <skipped/>
  </testcase> <!-- test1 -->
  <system-out/>
  <testcase classname="RetryAllTestCases.MyTests" name="test1" time="0.000">
    <skipped/>
  </testcase> <!-- test1 -->
  <system-out/>
  <testcase classname="RetryAllTestCases.MyTests" name="test2" time="0.001">
    <skipped/>
  </testcase> <!-- test2 -->
  <system-out/>
  <testcase classname="RetryAllTestCases.MyTests" name="test2" time="0.001">
    <skipped/>
  </testcase> <!-- test2 -->
  <system-out/>
  <testcase classname="RetryAllTestCases.MyTests" name="test2" time="0.000">
    <skipped/>
  </testcase> <!-- test2 -->
  <system-out/>
  <testcase classname="RetryAllTestCases.MyTests" name="test2" time="0.001">
    <skipped/>
  </testcase> <!-- test2 -->
  <system-out/>
  <testcase classname="RetryAllTestCases.MyTests" name="test1" time="0.000">
    <skipped/>
  </testcase> <!-- test1 -->
  <system-out/>
  <testcase classname="RetryAllTestCases.MyTests" name="test1" time="0.001">
    <skipped/>
  </testcase> <!-- test1 -->
  <system-out/>
  <testcase classname="RetryAllTestCases.MyTests" name="test1" time="0.000">
    <skipped/>
  </testcase> <!-- test1 -->
  <system-out/>
  <testcase classname="RetryAllTestCases.MyTests" name="test2" time="0.000">
    <skipped/>
  </testcase> <!-- test2 -->
  <system-out/>
  <testcase classname="RetryAllTestCases.MyTests" name="test2" time="0.001">
    <skipped/>
  </testcase> <!-- test2 -->
  <system-out/>
  <testcase classname="RetryAllTestCases.MyTests" name="test2" time="0.000">
    <failure message="expected [false] but found [true]" type="java.lang.AssertionError">
      <![CDATA[java.lang.AssertionError: expected [false] but found [true]
at org.testng.Assert.fail(Assert.java:99)
at org.testng.Assert.failNotEquals(Assert.java:1037)
at org.testng.Assert.assertEqualsImpl(Assert.java:140)
at org.testng.Assert.assertEquals(Assert.java:122)
at org.testng.Assert.assertEquals(Assert.java:819)
at org.testng.Assert.assertEquals(Assert.java:829)
at RetryAllTestCases.MyTests.test2(MyTests.java:15)
at java.base/jdk.internal.reflect.DirectMethodHandleAccessor.invoke(DirectMethodHandleAccessor.java:104)
at java.base/java.lang.reflect.Method.invoke(Method.java:578)
at org.testng.internal.MethodInvocationHelper.invokeMethod(MethodInvocationHelper.java:133)
at org.testng.internal.TestInvoker.invokeMethod(TestInvoker.java:598)
at org.testng.internal.TestInvoker.retryFailed(TestInvoker.java:213)
at org.testng.internal.MethodRunner.runInSequence(MethodRunner.java:58)
at org.testng.internal.TestInvoker$MethodInvocationAgent.invoke(TestInvoker.java:824)
at org.testng.internal.TestInvoker.invokeTestMethods(TestInvoker.java:146)
at org.testng.internal.TestMethodWorker.invokeTestMethods(TestMethodWorker.java:146)
at org.testng.internal.TestMethodWorker.run(TestMethodWorker.java:128)
at java.base/java.util.ArrayList.forEach(ArrayList.java:1511)
at org.testng.TestRunner.privateRun(TestRunner.java:794)
at org.testng.TestRunner.run(TestRunner.java:596)
at org.testng.SuiteRunner.runTest(SuiteRunner.java:377)
at org.testng.SuiteRunner.runSequentially(SuiteRunner.java:371)
at org.testng.SuiteRunner.privateRun(SuiteRunner.java:332)
at org.testng.SuiteRunner.run(SuiteRunner.java:276)
at org.testng.SuiteRunnerWorker.runSuite(SuiteRunnerWorker.java:53)
at org.testng.SuiteRunnerWorker.run(SuiteRunnerWorker.java:96)
at org.testng.TestNG.runSuitesSequentially(TestNG.java:1212)
at org.testng.TestNG.runSuitesLocally(TestNG.java:1134)
at org.testng.TestNG.runSuites(TestNG.java:1063)
at org.testng.TestNG.run(TestNG.java:1031)
at org.testng.remote.AbstractRemoteTestNG.run(AbstractRemoteTestNG.java:115)
at org.testng.remote.RemoteTestNG.initAndRun(RemoteTestNG.java:251)
at org.testng.remote.RemoteTestNG.main(RemoteTestNG.java:77)
]]>
    </failure>
  </testcase> <!-- test2 -->
  <system-out/>
  <testcase classname="RetryAllTestCases.MyTests" name="test3">
    <skipped/>
  </testcase> <!-- test3 -->
  <system-out/>
</testsuite> <!-- RetryAllTestCases.MyTests -->
